В C++ можно создать одну общую функцию для обработки ошибок, которая будет принимать в качестве аргументов информацию об ошибке. Ниже приведен пример такой функции:

```cpp
#include <iostream>
#include <stdexcept>
#include <string>

// Общая функция для обработки ошибок
void handle_error(const std::exception& e, const std::string& additional_info = "") {
    std::cerr << "Error: " << e.what() << std::endl;
    if (!additional_info.empty()) {
        std::cerr << "Additional info: " << additional_info << std::endl;
    }
}

// Пример функции, которая может генерировать исключения
void some_function() {
    throw std::runtime_error("Something went wrong in some_function");
}

int main() {
    try {
        some_function();
    } catch (const std::exception& e) {
        handle_error(e, "This error occurred during the execution of some_function");
    }

    return 0;
}
```

В этом примере функция `handle_error` принимает ссылку на базовый класс исключений `std::exception` и необязательную дополнительную информацию в виде строки. В функции `main` вызывается функция `some_function`, которая может генерировать исключения. Если происходит исключение, оно перехватывается блоком `catch`, и вызывается функция `handle_error` для обработки ошибки.


#cpp #theory 